{
    "registryname": "converter",
    "localizedname": "Converter",
    "requires-blueprint": true,
    "color": "2c2c2c",
    "parts": [
        {
            "x": 2,
            "y": 3,
            "z": 0,
            "elements": [
                "thaumcraft:stone_arcane@0"
            ]
        },
        {
            "x": 2,
            "y": 3,
            "z": 1,
            "elements": [
                "mekanism:basicblock@10"
            ]
        },
        {
            "x": 2,
            "y": 3,
            "z": 2,
            "elements": [
                "mekanism:basicblock@10"
            ]
        },
        {
            "x": 2,
            "y": 3,
            "z": 3,
            "elements": [
                "mekanism:basicblock@10"
            ]
        },
        {
            "x": 2,
            "y": 3,
            "z": 4,
            "elements": [
                "thaumcraft:stone_arcane@0"
            ]
        },
        {
            "x": 0,
            "y": 4,
            "z": 0,
            "elements": [
                "thaumcraft:stone_arcane@0"
            ]
        },
        {
            "x": 0,
            "y": 4,
            "z": 1,
            "elements": [
                "modularmachinery:blockcasing@1"
            ]
        },
        {
            "x": -2,
            "y": 1,
            "z": 4,
            "elements": [
                "thaumcraft:stone_arcane@0"
            ]
        },
        {
            "x": 0,
            "y": 4,
            "z": 2,
            "elements": [
                "jaopca:block.aquamarine@0"
            ]
        },
        {
            "x": -2,
            "y": 1,
            "z": 2,
            "elements": [
                "mekanism:basicblock@10"
            ]
        },
        {
            "x": -2,
            "y": 1,
            "z": 3,
            "elements": [
                "mekanism:basicblock@10"
            ]
        },
        {
            "x": -2,
            "y": 1,
            "z": 0,
            "elements": [
                "thaumcraft:stone_arcane@0"
            ]
        },
        {
            "x": -2,
            "y": 1,
            "z": 1,
            "elements": [
                "mekanism:basicblock@10"
            ]
        },
        {
            "x": 0,
            "y": 0,
            "z": 4,
            "elements": [
                "modulardiversity:blockmanainputhatch@0"
            ]
        },
        {
            "x": 0,
            "y": 0,
            "z": 3,
            "elements": [
                "modularmachinery:blockcasing@2"
            ]
        },
        {
            "x": 0,
            "y": 0,
            "z": 0,
            "elements": [
                "modularmachinery:blockcontroller@0"
            ]
        },
        {
            "x": 0,
            "y": 0,
            "z": 2,
            "elements": [
                "jaopca:block.aquamarine@0"
            ]
        },
        {
            "x": 1,
            "y": 2,
            "z": 4,
            "elements": [
                "mekanism:basicblock@10"
            ]
        },
        {
            "x": 0,
            "y": 0,
            "z": 1,
            "elements": [
                "modularmachinery:blockcasing@2"
            ]
        },
        {
            "x": -1,
            "y": 3,
            "z": 4,
            "elements": [
                "mekanism:basicblock@10"
            ]
        },
        {
            "x": 1,
            "y": 2,
            "z": 3,
            "elements": [
                "actuallyadditions:block_crystal_empowered@0"
            ]
        },
        {
            "x": -1,
            "y": 3,
            "z": 3,
            "elements": [
                "actuallyadditions:block_misc@2"
            ]
        },
        {
            "x": 1,
            "y": 2,
            "z": 2,
            "elements": [
                "contenttweaker:aluminum_coil_block@0"
            ]
        },
        {
            "x": -1,
            "y": 3,
            "z": 2,
            "elements": [
                "actuallyadditions:block_crystal_empowered@0"
            ]
        },
        {
            "x": 1,
            "y": 2,
            "z": 1,
            "elements": [
                "actuallyadditions:block_crystal_empowered@0"
            ]
        },
        {
            "x": -1,
            "y": 3,
            "z": 1,
            "elements": [
                "actuallyadditions:block_misc@2"
            ]
        },
        {
            "x": 1,
            "y": 2,
            "z": 0,
            "elements": [
                "mekanism:basicblock@10"
            ]
        },
        {
            "x": -1,
            "y": 3,
            "z": 0,
            "elements": [
                "mekanism:basicblock@10"
            ]
        },
        {
            "x": -2,
            "y": 4,
            "z": 0,
            "elements": [
                "modularmachinery:blockcasing@4"
            ]
        },
        {
            "x": -2,
            "y": 4,
            "z": 2,
            "elements": [
                "modularmachinery:blockfluidinputhatch@0"
            ]
        },
        {
            "x": -2,
            "y": 4,
            "z": 1,
            "elements": [
                "modularmachinery:blockfluidinputhatch@0"
            ]
        },
        {
            "x": -2,
            "y": 4,
            "z": 4,
            "elements": [
                "modularmachinery:blockcasing@4"
            ]
        },
        {
            "x": -2,
            "y": 4,
            "z": 3,
            "elements": [
                "modularmachinery:blockfluidinputhatch@0"
            ]
        },
        {
            "x": 0,
            "y": 3,
            "z": 1,
            "elements": [
                "actuallyadditions:block_crystal_empowered@0"
            ]
        },
        {
            "x": 0,
            "y": 3,
            "z": 0,
            "elements": [
                "mekanism:basicblock@10"
            ]
        },
        {
            "x": 0,
            "y": 3,
            "z": 3,
            "elements": [
                "actuallyadditions:block_crystal_empowered@0"
            ]
        },
        {
            "x": 0,
            "y": 3,
            "z": 2,
            "elements": [
                "contenttweaker:aluminum_coil_block@0"
            ]
        },
        {
            "x": 1,
            "y": 1,
            "z": 0,
            "elements": [
                "mekanism:basicblock@10"
            ]
        },
        {
            "x": 0,
            "y": 3,
            "z": 4,
            "elements": [
                "mekanism:basicblock@10"
            ]
        },
        {
            "x": 1,
            "y": 1,
            "z": 4,
            "elements": [
                "mekanism:basicblock@10"
            ]
        },
        {
            "x": 1,
            "y": 1,
            "z": 3,
            "elements": [
                "actuallyadditions:block_misc@2"
            ]
        },
        {
            "x": 1,
            "y": 1,
            "z": 2,
            "elements": [
                "actuallyadditions:block_crystal_empowered@0"
            ]
        },
        {
            "x": 1,
            "y": 1,
            "z": 1,
            "elements": [
                "actuallyadditions:block_misc@2"
            ]
        },
        {
            "x": 1,
            "y": 4,
            "z": 0,
            "elements": [
                "thaumcraft:stone_arcane@0"
            ]
        },
        {
            "x": 1,
            "y": 4,
            "z": 1,
            "elements": [
                "mekanism:basicblock@10"
            ]
        },
        {
            "x": -2,
            "y": 2,
            "z": 0,
            "elements": [
                "thaumcraft:stone_arcane@0"
            ]
        },
        {
            "x": 2,
            "y": 0,
            "z": 0,
            "elements": [
                "modularmachinery:blockcasing@4"
            ]
        },
        {
            "x": -2,
            "y": 2,
            "z": 2,
            "elements": [
                "jaopca:block.aquamarine@0"
            ]
        },
        {
            "x": -2,
            "y": 2,
            "z": 1,
            "elements": [
                "mekanism:basicblock@10"
            ]
        },
        {
            "x": -2,
            "y": 2,
            "z": 4,
            "elements": [
                "thaumcraft:stone_arcane@0"
            ]
        },
        {
            "x": 1,
            "y": 4,
            "z": 4,
            "elements": [
                "thaumcraft:stone_arcane@0"
            ]
        },
        {
            "x": 2,
            "y": 0,
            "z": 2,
            "elements": [
                "modularmachinery:blockoutputbus@0"
            ]
        },
        {
            "x": -2,
            "y": 2,
            "z": 3,
            "elements": [
                "mekanism:basicblock@10"
            ]
        },
        {
            "x": 2,
            "y": 0,
            "z": 1,
            "elements": [
                "modularmachinery:blockoutputbus@0"
            ]
        },
        {
            "x": 1,
            "y": 4,
            "z": 2,
            "elements": [
                "modularmachinery:blockcasing@1"
            ]
        },
        {
            "x": 2,
            "y": 0,
            "z": 4,
            "elements": [
                "modularmachinery:blockcasing@4"
            ]
        },
        {
            "x": 2,
            "y": 0,
            "z": 3,
            "elements": [
                "modularmachinery:blockoutputbus@0"
            ]
        },
        {
            "x": 1,
            "y": 4,
            "z": 3,
            "elements": [
                "mekanism:basicblock@10"
            ]
        },
        {
            "x": 1,
            "y": 0,
            "z": 4,
            "elements": [
                "thaumcraft:stone_arcane@0"
            ]
        },
        {
            "x": 1,
            "y": 0,
            "z": 3,
            "elements": [
                "modularmachinery:blockcasing@2"
            ]
        },
        {
            "x": 1,
            "y": 0,
            "z": 2,
            "elements": [
                "modularmachinery:blockcasing@2"
            ]
        },
        {
            "x": 1,
            "y": 0,
            "z": 1,
            "elements": [
                "modularmachinery:blockcasing@2"
            ]
        },
        {
            "x": 1,
            "y": 0,
            "z": 0,
            "elements": [
                "thaumcraft:stone_arcane@0"
            ]
        },
        {
            "x": -1,
            "y": 1,
            "z": 4,
            "elements": [
                "mekanism:basicblock@10"
            ]
        },
        {
            "x": -1,
            "y": 1,
            "z": 3,
            "elements": [
                "actuallyadditions:block_misc@2"
            ]
        },
        {
            "x": -1,
            "y": 1,
            "z": 2,
            "elements": [
                "actuallyadditions:block_crystal_empowered@0"
            ]
        },
        {
            "x": 2,
            "y": 1,
            "z": 4,
            "elements": [
                "thaumcraft:stone_arcane@0"
            ]
        },
        {
            "x": -1,
            "y": 4,
            "z": 3,
            "elements": [
                "mekanism:basicblock@10"
            ]
        },
        {
            "x": -1,
            "y": 4,
            "z": 2,
            "elements": [
                "modularmachinery:blockcasing@1"
            ]
        },
        {
            "x": -1,
            "y": 1,
            "z": 1,
            "elements": [
                "actuallyadditions:block_misc@2"
            ]
        },
        {
            "x": -1,
            "y": 4,
            "z": 1,
            "elements": [
                "mekanism:basicblock@10"
            ]
        },
        {
            "x": -1,
            "y": 1,
            "z": 0,
            "elements": [
                "mekanism:basicblock@10"
            ]
        },
        {
            "x": -1,
            "y": 4,
            "z": 0,
            "elements": [
                "thaumcraft:stone_arcane@0"
            ]
        },
        {
            "x": -2,
            "y": 3,
            "z": 3,
            "elements": [
                "mekanism:basicblock@10"
            ]
        },
        {
            "x": 0,
            "y": 2,
            "z": 2,
            "elements": [
                "botania:storage@1"
            ]
        },
        {
            "x": 2,
            "y": 1,
            "z": 0,
            "elements": [
                "thaumcraft:stone_arcane@0"
            ]
        },
        {
            "x": 2,
            "y": 1,
            "z": 1,
            "elements": [
                "mekanism:basicblock@10"
            ]
        },
        {
            "x": -2,
            "y": 3,
            "z": 2,
            "elements": [
                "mekanism:basicblock@10"
            ]
        },
        {
            "x": 0,
            "y": 2,
            "z": 1,
            "elements": [
                "contenttweaker:aluminum_coil_block@0"
            ]
        },
        {
            "x": 0,
            "y": 2,
            "z": 4,
            "elements": [
                "jaopca:block.aquamarine@0"
            ]
        },
        {
            "x": 2,
            "y": 1,
            "z": 2,
            "elements": [
                "mekanism:basicblock@10"
            ]
        },
        {
            "x": 1,
            "y": 3,
            "z": 3,
            "elements": [
                "actuallyadditions:block_misc@2"
            ]
        },
        {
            "x": -1,
            "y": 4,
            "z": 4,
            "elements": [
                "thaumcraft:stone_arcane@0"
            ]
        },
        {
            "x": 2,
            "y": 1,
            "z": 3,
            "elements": [
                "mekanism:basicblock@10"
            ]
        },
        {
            "x": -2,
            "y": 3,
            "z": 4,
            "elements": [
                "thaumcraft:stone_arcane@0"
            ]
        },
        {
            "x": 0,
            "y": 2,
            "z": 3,
            "elements": [
                "contenttweaker:aluminum_coil_block@0"
            ]
        },
        {
            "x": 1,
            "y": 3,
            "z": 4,
            "elements": [
                "mekanism:basicblock@10"
            ]
        },
        {
            "x": -2,
            "y": 3,
            "z": 1,
            "elements": [
                "mekanism:basicblock@10"
            ]
        },
        {
            "x": 0,
            "y": 2,
            "z": 0,
            "elements": [
                "jaopca:block.aquamarine@0"
            ]
        },
        {
            "x": -2,
            "y": 3,
            "z": 0,
            "elements": [
                "thaumcraft:stone_arcane@0"
            ]
        },
        {
            "x": -2,
            "y": 0,
            "z": 3,
            "elements": [
                "modularmachinery:blockinputbus@0"
            ]
        },
        {
            "x": -2,
            "y": 0,
            "z": 4,
            "elements": [
                "modularmachinery:blockcasing@4"
            ]
        },
        {
            "x": -2,
            "y": 0,
            "z": 1,
            "elements": [
                "modularmachinery:blockinputbus@0"
            ]
        },
        {
            "x": -2,
            "y": 0,
            "z": 2,
            "elements": [
                "modularmachinery:blockinputbus@0"
            ]
        },
        {
            "x": 1,
            "y": 3,
            "z": 1,
            "elements": [
                "actuallyadditions:block_misc@2"
            ]
        },
        {
            "x": 1,
            "y": 3,
            "z": 2,
            "elements": [
                "actuallyadditions:block_crystal_empowered@0"
            ]
        },
        {
            "x": 1,
            "y": 3,
            "z": 0,
            "elements": [
                "mekanism:basicblock@10"
            ]
        },
        {
            "x": -2,
            "y": 0,
            "z": 0,
            "elements": [
                "modularmachinery:blockcasing@4"
            ]
        },
        {
            "x": 2,
            "y": 2,
            "z": 0,
            "elements": [
                "thaumcraft:stone_arcane@0"
            ]
        },
        {
            "x": 2,
            "y": 2,
            "z": 1,
            "elements": [
                "mekanism:basicblock@10"
            ]
        },
        {
            "x": 2,
            "y": 2,
            "z": 2,
            "elements": [
                "jaopca:block.aquamarine@0"
            ]
        },
        {
            "x": -1,
            "y": 0,
            "z": 3,
            "elements": [
                "modularmachinery:blockcasing@2"
            ]
        },
        {
            "x": -1,
            "y": 0,
            "z": 2,
            "elements": [
                "modularmachinery:blockcasing@2"
            ]
        },
        {
            "x": -1,
            "y": 0,
            "z": 1,
            "elements": [
                "modularmachinery:blockcasing@2"
            ]
        },
        {
            "x": -1,
            "y": 0,
            "z": 0,
            "elements": [
                "thaumcraft:stone_arcane@0"
            ]
        },
        {
            "x": -1,
            "y": 0,
            "z": 4,
            "elements": [
                "thaumcraft:stone_arcane@0"
            ]
        },
        {
            "x": 2,
            "y": 2,
            "z": 3,
            "elements": [
                "mekanism:basicblock@10"
            ]
        },
        {
            "x": 2,
            "y": 2,
            "z": 4,
            "elements": [
                "thaumcraft:stone_arcane@0"
            ]
        },
        {
            "x": 2,
            "y": 4,
            "z": 0,
            "elements": [
                "modularmachinery:blockcasing@4"
            ]
        },
        {
            "x": 2,
            "y": 4,
            "z": 1,
            "elements": [
                "modularmachinery:blockfluidoutputhatch@0"
            ]
        },
        {
            "x": 2,
            "y": 4,
            "z": 2,
            "elements": [
                "modularmachinery:blockfluidoutputhatch@0"
            ]
        },
        {
            "x": 2,
            "y": 4,
            "z": 3,
            "elements": [
                "modularmachinery:blockfluidoutputhatch@0"
            ]
        },
        {
            "x": 2,
            "y": 4,
            "z": 4,
            "elements": [
                "modularmachinery:blockcasing@4"
            ]
        },
        {
            "x": -1,
            "y": 2,
            "z": 1,
            "elements": [
                "actuallyadditions:block_crystal_empowered@0"
            ]
        },
        {
            "x": -1,
            "y": 2,
            "z": 0,
            "elements": [
                "mekanism:basicblock@10"
            ]
        },
        {
            "x": 0,
            "y": 4,
            "z": 4,
            "elements": [
                "thaumcraft:stone_arcane@0"
            ]
        },
        {
            "x": -1,
            "y": 2,
            "z": 4,
            "elements": [
                "mekanism:basicblock@10"
            ]
        },
        {
            "x": 0,
            "y": 4,
            "z": 3,
            "elements": [
                "modularmachinery:blockcasing@1"
            ]
        },
        {
            "x": -1,
            "y": 2,
            "z": 3,
            "elements": [
                "actuallyadditions:block_crystal_empowered@0"
            ]
        },
        {
            "x": -1,
            "y": 2,
            "z": 2,
            "elements": [
                "contenttweaker:aluminum_coil_block@0"
            ]
        },
        {
            "x": 0,
            "y": 1,
            "z": 1,
            "elements": [
                "actuallyadditions:block_crystal_empowered@0"
            ]
        },
        {
            "x": 0,
            "y": 1,
            "z": 0,
            "elements": [
                "mekanism:basicblock@10"
            ]
        },
        {
            "x": 0,
            "y": 1,
            "z": 3,
            "elements": [
                "actuallyadditions:block_crystal_empowered@0"
            ]
        },
        {
            "x": 0,
            "y": 1,
            "z": 2,
            "elements": [
                "contenttweaker:aluminum_coil_block@0"
            ]
        },
        {
            "x": 0,
            "y": 1,
            "z": 4,
            "elements": [
                "mekanism:basicblock@10"
            ]
        }
    ]}